Workbook

Sheet ลิสต์รายการโอนงิน
A1: รายการโอนรายวัน Bualuang Mbanking | M1: สำรองเจ้าหน้าที่ | N1: รายเดือนปราบปรามภาค8 11/68 - 4/69 | O1: ปป. ภาค8 | P1: รอโกจุ่งแจ้งเลขที่บัญชีมาใหม่คะ | R1: รายการโอน Bualuang Mbanking
A2: ประจำเดือน พฤษภาคม 2569 (5/2026) | R2: =A2 -> ประจำเดือน พฤษภาคม 2569 (5/2026)
A3: Voucher | B3: Pst | C3: วันที่ | D3: A/Cย่อย | E3: ชื่อบัญชี | F3: รายละเอียด | G3: จ่ายให้ | H3: BY | I3: รับ | J3: จ่าย | K3: คงเหลือ | L3: หมายเหตุ | R3: ลำดับ | S3: รายการเบิกM-banking | T3: ยอดเงิน | V3: ลำดับ | W3: รายการเบิกM-banking | X3: ยอดเงิน | Z3: ลำดับ | AA3: รายการเบิกM-banking | AB3: ยอดเงิน | AD3: ลำดับ | AE3: ป้ายชื่อแถว | AF3: ผลรวม ของ จ่าย | AH3: DATA
C4: ยกมา | K4: 3587191.6 | R4: 1 | S4: กรรมการ | T4: 3763616.7 | V4: ยอดยกมา | X4: =T17 -> 11619301 | Z4: ยอดยกมา | AB4: =X21 -> 11619301 | AD4: 1 | AE4: CH-Exp | AF4: 456647.66 | AH4: BBL
A5: M69-05-001 | C5: 46143 | E5: Yส่วนตัว | F5: โอนเงินให้มะโถ้ย 5.) | G5: แฟนโกหย่ง | H5: =VLOOKUP(G5,บัญชีโอน!$B:$D,3,FALSE) -> BBL | J5: 150000 | K5: =K4+I5-J5 -> 3437191.6 | R5: 2 | S5: ร้านค้า | T5: 2605961 | V5: 28 | Z5: 14 | AA5: คานเรือโกตา | AB5: 133900 | AD5: 2 | AE5: EXP C-PAC | AF5: 25000 | AH5: SCB
A6: M69-05-002 | C6: 46143 | E6: โกต้งส่วนตัว | F6: ให้จี้เกี่ยใช้ 5.) (ปิดอ่าว#2) | G6: จี้เมธ์ | H6: =VLOOKUP(G6,บัญชีโอน!$B:$D,3,FALSE) -> TTB | J6: 100000 | K6: =K5+I6-J6 -> 3337191.6 | R6: 3 | S6: โรงงานมะริด | T6: 1449734 | V6: 29 | Z6: 15 | AA6: สำรองโกจุ่ง | AB6: 115707 | AD6: 3 | AE6: Exp M-SHOP | AF6: 56910 | AH6: Kbank
A7: M69-05-003 | C7: 46143 | E7: โกเจี้ยวส่วนตัว | F7: เงินเดือนโกเจี้ยวและครอบครัว 5.) | H7: =VLOOKUP(G7,บัญชีโอน!$B:$D,3,FALSE) -> #N/A | J7: 495000 | K7: =K6+I7-J7 -> 2842191.6 | R7: 4 | S7: HHT ICE-3 | T7: 766950 | V7: 30 | Z7: 16 | AA7: HHT ICE | AB7: 25625 | AD7: 4 | AE7: Exp MYEIK | AF7: 10500 | AH7: KTB
A8: M69-05-004 | C8: 46143 | E8: CH-Exp | F8: รายเดือนครอบครัวโกช่อง 5.) | H8: =VLOOKUP(G8,บัญชีโอน!$B:$D,3,FALSE) -> #N/A | J8: 250000 | K8: =K7+I8-J8 -> 2592191.6 | R8: 5 | S8: ค่าปลาเรือนอก | T8: 600091 | V8: 31 | Z8: 17 | AA8: EXP C-PAC | AB8: 25000 | AD8: 5 | AE8: FM | AF8: 176901 | AH8: TTB
A9: M69-05-005 | C9: 46143 | E9: สำรองเจ้าหน้าที่ | F9: รายเดือนสรรพสามิต 5.) | G9: สรรพสามิต | H9: =VLOOKUP(G9,บัญชีโอน!$B:$D,3,FALSE) -> KTB | J9: 5000 | K9: =K8+I9-J9 -> 2587191.6 | R9: 6 | S9: KPS-ห้องเย็น | T9: 600000 | V9: 32 | Z9: 18 | AA9: แพกลุ่มเกษตร | AB9: 23862 | AD9: 6 | AE9: HHT ICE | AF9: 25625 | AH9: ออมสิน
A10: M69-05-006 | C10: 46143 | E10: OFF | F10: เงินเดือนน้องอร(ชมรมแพปลา) 4.) | G10: โกจุ่ง | H10: =VLOOKUP(G10,บัญชีโอน!$B:$D,3,FALSE) -> BBL | J10: 2500 | K10: =K9+I10-J10 -> 2584691.6 | R10: 7 | S10: โกโรจน์(ถัง) | T10: 534600 | V10: 33 | Z10: 19 | AA10: YNTZ ICE | AB10: 11556 | AD10: 7 | AE10: HHT ICE-3 | AF10: 766950 | AH10: กรุงศรี
A11: M69-05-007 | C11: 46146 | E11: Exp MYEIK | F11: โอนเงิน (โกหย่งแจ้งให้โอน) | G11: MS.ZIN THU HAN | H11: =VLOOKUP(G11,บัญชีโอน!$B:$D,3,FALSE) -> P-Pay | J11: 4000 | K11: =K10+I11-J11 -> 2580691.6 | M11: =C9 -> 46143 | N11: รับ | O11: จ่าย | P11: คงเหลือ(2ลบ.) | Q11: 1 | R11: 8 | S11: สำรองเจ้าหน้าที่ | T11: 308972 | V11: 34 | Z11: 20 | AA11: Exp MYEIK | AB11: 10500 | AD11: 8 | AE11: ICE KAWTHAUNG | AF11: 11820 | AH11: P-pay
A12: M69-05-008 | C12: 46146 | E12: Exp MYEIK | F12: ค่ารถและค่าไกด์ (โกหย่งแจ้งให้โอน) | G12: ยี่เอ้ง | H12: =VLOOKUP(G12,บัญชีโอน!$B:$D,3,FALSE) -> BBL | J12: 6500 | K12: =K11+I12-J12 -> 2574191.6 | M12: รวมสุทธิ | N12: =SUM(I4:I12) -> 0 | O12: =SUM(J4:J12) -> 1013000 | P12: =2000000-O12 -> 987000 | R12: 9 | S12: เรือปั่นไฟ HHT-12 | T12: 270500 | V12: 35 | Z12: 21 | AA12: รถน้ำ | AB12: 10102 | AD12: 9 | AE12: Ko Than Win(z) | AF12: 200000 | AH12: TRUE
A13: M69-05-009 | C13: 46147 | E13: ต้นน้ำจืด | F13: ค่าน้ำจืด 4.) (128คันx140 ) | G13: ต้นน้ำจืด | H13: =VLOOKUP(G13,บัญชีโอน!$B:$D,3,FALSE) -> KTB | J13: 17920 | K13: =K12+I13-J13 -> 2556271.6 | R13: 10 | S13: จี้หม่วย | T13: 200569 | V13: 36 | Z13: 22 | AA13: เรือภายใน | AB13: 6754 | AD13: 10 | AE13: KPS-ท่าเรือเขานางหงส์ | AF13: 78360 | AH13: QR CODE
A14: M69-05-010 | C14: 46147 | E14: บ่อน้ำตาอิน | F14: ค่าน้ำจืด 4.) (48คันx150 ) | G14: บ่อน้ำตาอิน | H14: =VLOOKUP(G14,บัญชีโอน!$B:$D,3,FALSE) -> TTB | J14: 7200 | K14: =K13+I14-J14 -> 2549071.6 | R14: 11 | S14: Ko Than Win(z) | T14: 200000 | V14: 37 | Z14: 23 | AA14: OFF | AB14: 3568.93 | AD14: 11 | AE14: KPS-ห้องเย็น | AF14: 600000
A15: M69-05-011 | C15: 46147 | E15: สำรองทิพย์ | F15: ค่าโทรศัพท์AIS 4.) | G15: ทิพย์ (ท่าเรือฯ)2 | H15: =VLOOKUP(G15,บัญชีโอน!$B:$D,3,FALSE) -> P-Pay | J15: 6754 | K15: =K14+I15-J15 -> 2542317.6 | R15: 12 | S15: FM | T15: 176901 | V15: 38 | Z15: 24 | AA15: YNTZ CONCRETE ทำงาน | AB15: 2247 | AD15: 12 | AE15: KSส่วนตัว (โกตาต้า) | AF15: 1000000 | AH15: ค่าปลาเรือนอก
A16: M69-05-012 | C16: 46147 | E16: ชาญสยามขนส่ง | F16: ค่าบรรทุกปลาป่นRGT#15/25-26 WTK (14คัน)(หักW/Tax 1,330.-) รอบที่ 1 | G16: ชาญสยามขนส่ง | H16: =VLOOKUP(G16,บัญชีโอน!$B:$D,3,FALSE) -> Kbank | J16: 131670 | K16: =K15+I16-J16 -> 2410647.6 | R16: 13 | S16: PT(1) | T16: 141406 | V16: 39 | Z16: 25 | AA16: ค่าใช้จ่ายเรือบาร์ช | AB16: 2140 | AD16: 13 | AE16: M-SHOP | AF16: 1367824 | AH16: KWB-Exp
A17: M69-05-013 | C17: 46147 | E17: สำรองโกจุ่ง | F17: ค่าเช่าธนสาร2/ใต้โต๊ะ/ตม. 4.) | G17: โกจุ่ง | H17: =VLOOKUP(G17,บัญชีโอน!$B:$D,3,FALSE) -> BBL | J17: 115707 | K17: =K16+I17-J17 -> 2294940.6 | R17: ยอดยกไป | T17: =SUM(T4:T16) -> 11619301 | V17: 50 | Z17: รวมรายการโอนMbanking | AB17: =SUM(AB4:AB16) -> 11990263 | AD17: 14 | AE17: MV.001 | AF17: 2140 | AH17: LB
A18: M69-05-014 | C18: 46147 | E18: โกต้งส่วนตัว | F18: ค่าของ 3.) (บ้านโกต้ง) | G18: มงคลพรหมระนอง | H18: =VLOOKUP(G18,บัญชีโอน!$B:$D,3,FALSE) -> อิสลาม | J18: 5450 | K18: =K17+I18-J18 -> 2289490.6 | V18: 51 | AD18: 15 | AE18: OFF | AF18: 3568.93 | AH18: TTL-59
A19: M69-05-015 | C19: 46147 | E19: M-SHOP | F19: ลวดเชื่อม | G19: THAI KOBELCO WELDING | H19: =VLOOKUP(G19,บัญชีโอน!$B:$D,3,FALSE) -> MIZUHO | J19: 379368 | K19: =K18+I19-J19 -> 1910122.6 | V19: 52 | AA19: ยอดยกมาจาก ก.พ.69 | AB19: =K4 -> 3587191.6 | AD19: 16 | AE19: PJ | AF19: 10480 | AH19: TS
A20: M69-05-016 | C20: 46147 | E20: บจ.โรงกลึงสองวัลย์ | F20: มัดจำ50% หน้าต่าง,ลูกบิด,ยางฟองน้ำ | G20: บจ.โรงกลึงสองวัลย์ | H20: =VLOOKUP(G20,บัญชีโอน!$B:$D,3,FALSE) -> Kbank | J20: 390300 | K20: =K19+I20-J20 -> 1519822.6 | V20: 53 | AA20: บวก นำเงินเข้าบัญชี | AB20: =I224 -> 12480724 | AD20: 17 | AE20: PT(1) | AF20: 141406 | AH20: U SOE THEIN | AI20: 600091
A21: M69-05-017 | C21: 46147 | E21: M-SHOP | F21: ทางแยกน้ำทองเหลือง(5ชิ้น) | G21: บจ.ยนตรการเมทัลเวิร์ค | H21: =VLOOKUP(G21,บัญชีโอน!$B:$D,3,FALSE) -> BBL | J21: 15789 | K21: =K20+I21-J21 -> 1504033.6 | V21: ยอดยกไป | X21: =SUM(X4:X20) -> 11619301 | AA21: หัก รายการเบิก | AB21: =-AB17 -> -11990263 | AD21: 18 | AE21: TK-โรงกลึง | AF21: 661712 | AH21: แพโกศิษย์-ขายปลา
A22: M69-05-018 | C22: 46147 | E22: M-SHOP | F22: ตะปูตะกั่ว 40กก. | G22: บจ.แกรนเมโทรฮาร์ดแวร์ | H22: =VLOOKUP(G22,บัญชีโอน!$B:$D,3,FALSE) -> Kbank | J22: 5800 | K22: =K21+I22-J22 -> 1498233.6 | M22: =C13 -> 46147 | N22: รับ | O22: จ่าย | P22: คงเหลือ(2ลบ.) | Q22: 2 | AA22: ยอดคงเหลือสุทธิ | AB22: =SUM(AB19:AB21) -> 4077653 | AC22: =K223-AB22 -> 0 | AD22: 19 | AE22: U SOE THEIN (YST) | AF22: 600091 | AH22: ช่างเพชร*ขายปลา
A23: M69-05-019 | C23: 46147 | E23: FM | F23: ค่าวิเคราะห์ปลาป่น #15/25-26 WTK (54x710.-) | G23: บจ.จรมิตร | H23: =VLOOKUP(G23,บัญชีโอน!$B:$D,3,FALSE) -> Kbank | J23: 38340 | K23: =K22+I23-J23 -> 1459893.6 | M23: รวมสุทธิ | N23: =SUM(I13:I23) -> 0 | O23: =SUM(J13:J23) -> 1114298 | P23: =2000000-O23 -> 885702 | AD23: 20 | AE23: UTK เรือรวม | AF23: 45000 | AH23: ย้อล่วย
C24: 46148 | E24: BBL 966-1 | F24: นำเงินเข้าบัญชี | H24: =VLOOKUP(G24,บัญชีโอน!$B:$D,3,FALSE) -> #N/A | I24: 3000000 | K24: =K23+I24-J24 -> 4459893.6 | AD24: 21 | AE24: YNTZ CONCRETE ทำงาน | AF24: 2247 | AH24: โกเซ็ก
A25: M69-05-020 | C25: 46148 | E25: ชาญสยามขนส่ง | F25: ค่าบรรทุกปลาป่นRGT#15/25-26 WTK (8คัน)(หักW/Tax 760.-) รอบที่ 2 | G25: ชาญสยามขนส่ง | H25: =VLOOKUP(G25,บัญชีโอน!$B:$D,3,FALSE) -> Kbank | J25: 75240 | K25: =K24+I25-J25 -> 4384653.6 | AD25: 22 | AE25: YNTZ C-PAC | AF25: 25000 | AH25: สำรองเรือUTK
A26: M69-05-021 | C26: 46148 | E26: โกชุ้น (ขนส่ง) | F26: ค่าบรรทุกปลาป่นRGT#15/25-26 WTK (6คัน)(หักW/Tax 570.-) | G26: โกชุ้น (ขนส่ง) | H26: =VLOOKUP(G26,บัญชีโอน!$B:$D,3,FALSE) -> Kbank | J26: 56430 | K26: =K25+I26-J26 -> 4328223.6 | AD26: 23 | AE26: YNTZ ICE | AF26: 11556 | AH26: ค่าปลาเรือนอก | AI26: =SUM(AI16:AI25) -> 600091
A27: M69-05-022 | C27: 46148 | E27: ตันเก้ง | F27: ค่าบรรทุกปลาป่นRGT#15/25-26 WTK (4คัน)(หักW/Tax 380.-) | G27: บจ.ทีเค.วัน ขนส่ง และ เซอร์วิส | H27: =VLOOKUP(G27,บัญชีโอน!$B:$D,3,FALSE) -> BBL | J27: 37620 | K27: =K26+I27-J27 -> 4290603.6 | AD27: 24 | AE27: Yส่วนตัว | AF27: 320000
A28: M69-05-023 | C28: 46148 | E28: ตั้งข้าวสาร | F28: ค่าบรรทุกปลาป่นRGT#15/25-26 WTK (4คัน)(หักW/Tax 380.-) | G28: ตั้งข้าวสาร | H28: =VLOOKUP(G28,บัญชีโอน!$B:$D,3,FALSE) -> Kbank | J28: 37620 | K28: =K27+I28-J28 -> 4252983.6 | AD28: 25 | AE28: กิจไพศาลวัสดุ | AF28: 23452 | AH28: อวนดำ
A29: M69-05-024 | C29: 46148 | E29: หจก.เสกศิริเนติพันธ์ | F29: ค่าบรรทุกปลาป่นRGT#15/25-26 WTK (4คัน)(หักW/Tax 380.-) | G29: หจก.เสกศิริเนติพันธ์ | H29: =VLOOKUP(G29,บัญชีโอน!$B:$D,3,FALSE) -> Kbank | J29: 37620 | K29: =K28+I29-J29 -> 4215363.6 | AD29: 26 | AE29: โกเจี้ยวส่วนตัว | AF29: 495000 | AH29: ค่าทัวร์อวนดำ
A30: M69-05-025 | C30: 46148 | E30: พรรณแก้ว(ขนส่ง) | F30: ค่าบรรทุกปลาป่นRGT#15/25-26 WTK (2คัน)(หักW/Tax 190.-) | G30: บจ.พรรณแก้วขนส่ง | H30: =VLOOKUP(G30,บัญชีโอน!$B:$D,3,FALSE) -> Kbank | J30: 18810 | K30: =K29+I30-J30 -> 4196553.6 | AD30: 27 | AE30: โกชุ้น (ขนส่ง) | AF30: 56430 | AH30: HHT-12
A31: M69-05-026 | C31: 46148 | E31: วาสนาอดิศรขนส่ง | F31: ค่าบรรทุกปลาป่นRGT#15/25-26 WTK (2คัน)(หักW/Tax 190.-) | G31: วาสนาอดิศร | H31: =VLOOKUP(G31,บัญชีโอน!$B:$D,3,FALSE) -> TTB | J31: 18810 | K31: =K30+I31-J31 -> 4177743.6 | AD31: 28 | AE31: โกต้งส่วนตัว | AF31: 680077 | AH31: HHT-15
A32: M69-05-027 | C32: 46148 | E32: แร่นอง(ขนส่ง) | F32: ค่าบรรทุกปลาป่นRGT#15/25-26 WTK (2คัน)(หักW/Tax 190.-) | G32: แร่นอง(ขนส่ง) | H32: =VLOOKUP(G32,บัญชีโอน!$B:$D,3,FALSE) -> SCB | J32: 18810 | K32: =K31+I32-J32 -> 4158933.6 | AD32: 29 | AE32: โกโรจน์(ถัง) | AF32: 534600 | AH32: HHT-19
A33: M69-05-028 | C33: 46148 | E33: พี่ธงชัย | F33: ค่าบรรทุกปลาป่นRGT#15/25-26 WTK (2คัน)(หักW/Tax 190.-) | G33: พี่ธงชัย | H33: =VLOOKUP(G33,บัญชีโอน!$B:$D,3,FALSE) -> Kbank | J33: 18810 | K33: =K32+I33-J33 -> 4140123.6 | AD33: 30 | AE33: คานเรือโกตา | AF33: 133900 | AH33: UTK-27
A34: M69-05-029 | C34: 46148 | E34: อันดามันขนส่ง(โกกิ้ว) | F34: ค่าบรรทุกปลาป่นRGT#15/25-26 WTK (2คัน)(หักW/Tax 190.-) | G34: อันดามันขนส่ง(โกกิ้ว) | H34: =VLOOKUP(G34,บัญชีโอน!$B:$D,3,FALSE) -> TTB | J34: 18810 | K34: =K33+I34-J34 -> 4121313.6 | M34: =C34 -> 46148 | N34: รับ | O34: จ่าย | P34: คงเหลือ(2ลบ.) | Q34: 3 | AD34: 31 | AE34: ค่าผ่านแพกิจไพศาล | AF34: 15000 | AH34: UTK-54
A35: M69-05-030 | C35: 46148 | E35: หจก.เอส.เอ็ม.พี ระนองเทรดดิ้ง | F35: ค่าบรรทุกปลาป่นRGT#15/25-26 WTK (4คัน)(หักW/Tax 380.-) | G35: หจก.เอส.เอ็ม.พี ระนองเทรดดิ้ง | H35: =VLOOKUP(G35,บัญชีโอน!$B:$D,3,FALSE) -> KTB | J35: 37620 | K35: =K34+I35-J35 -> 4083693.6 | M35: รวมสุทธิ | N35: =SUM(I24:I35) -> 3000000 | O35: =SUM(J24:J35) -> 376200 | P35: =2000000-O35 -> 1623800 | AD35: 32 | AE35: จี้หม่วย | AF35: 200569 | AH35: UTK-63
A36: 035/1738 | C36: 46149 | E36: HHT-S | F36: รับค่าของ | H36: =VLOOKUP(G36,บัญชีโอน!$B:$D,3,FALSE) -> #N/A | I36: 143040 | K36: =K35+I36-J36 -> 4226733.6 | AD36: 33 | AE36: ชัยวัฒน์การช่าง | AF36: 121795 | AH36: MIN OO บ/ช.รวมค่าทัวร์อวนดำ
A37: M69-05-031 | C37: 46149 | E37: โกต้งส่วนตัว | F37: ค่าของ 4.) (อาหารไก่, ตาข่ายกรองแสง,สปริงฯ) | G37: บจ.มานิตย์ระนองการเกษตร | H37: =VLOOKUP(G37,บัญชีโอน!$B:$D,3,FALSE) -> SCB | J37: 4950 | K37: =K36+I37-J37 -> 4221783.6 | AD37: 34 | AE37: ช่างเดช-ต่อเรือเหล็ก(พ่นทราย) | AF37: 792000 | AH37: อวนดำ | AI37: =SUM(AI29:AI36) -> 0
A38: M69-05-032 | C38: 46149 | E38: KSส่วนตัว (โกตาต้า) | F38: เบิกเงิน | G38: MR.ZAW MYO TUN | H38: =VLOOKUP(G38,บัญชีโอน!$B:$D,3,FALSE) -> BBL | J38: 500000 | K38: =K37+I38-J38 -> 3721783.6 | AD38: 35 | AE38: ช่างพร | AF38: 60000
A39: M69-05-033 | C39: 46149 | E39: TK-โรงกลึง | F39: ค่าซ่อมและค่าอะไหล่,เงินทุนค่าอะไหล่ฯ 4.) | G39: โกแดง | H39: =VLOOKUP(G39,บัญชีโอน!$B:$D,3,FALSE) -> KTB | J39: 661712 | K39: =K38+I39-J39 -> 3060071.6 | AD39: 36 | AE39: ช่างเยื้อน | AF39: 52500 | AH39: เรือภายใน
A40: M69-05-034 | C40: 46149 | E40: HHT ICE-3 | F40: น้ำยาโฟม 5,053กก. | G40: นายสมบูรณ์ พงษ์ขยัน | H40: =VLOOKUP(G40,บัญชีโอน!$B:$D,3,FALSE) -> Kbank | J40: 757950 | K40: =K39+I40-J40 -> 2302121.6 | M40: =C36 -> 46149 | N40: รับ | O40: จ่าย | P40: คงเหลือ(2ลบ.) | Q40: 4 | AD40: 37 | AE40: ชาญสยามขนส่ง | AF40: 206910 | AH40: สำรองทิพย์ | AI40: 6754
...

Sheet รายงานโอนเงินแบบรายยปี
A1: ลำดับ | B1: แผนก | C1: ชื่อบัญชี | D1: ม.ค. | E1: ก.พ. | F1: มี.ค. | G1: เม.ย. | H1: พ.ค. | I1: มิ.ย. | J1: ก.ค. | K1: ส.ค. | L1: ก.ย. | M1: ต.ค. | O1: พ.ย. | P1: ธ.ค. | Q1: รวม
A2: 1 | C2: % HHT-14 | Q2: =SUM(D2:P2) -> 0
C3: A-10 | Q3: =SUM(D3:P3) -> 0
A4: 2 | C4: A-12 | Q4: =SUM(D4:P4) -> 0
A5: 3 | C5: A-18 | Q5: =SUM(D5:P5) -> 0
C6: ABC ขายปลาอวนดำ | Q6: =SUM(D6:P6) -> 0
A7: 4 | C7: ACT.18 | Q7: =SUM(D7:P7) -> 0
C8: APS-7 | Q8: =SUM(D8:P8) -> 0
A9: 5 | C9: B-5 | Q9: =SUM(D9:P9) -> 0
A10: 6 | C10: BBL 1326-7 | Q10: =SUM(D10:P10) -> 0
A11: 7 | C11: BBL 1337-4 (KPS) | Q11: =SUM(D11:P11) -> 0
A12: 8 | C12: BBL 15850-3 (T&Y) | Q12: =SUM(D12:P12) -> 0
A13: 9 | C13: BBL 1765-6 | Q13: =SUM(D13:P13) -> 0
A14: 10 | C14: BBL 4241-4 | Q14: =SUM(D14:P14) -> 0
A15: 11 | C15: BBL 45002-5(FIX11M.) | Q15: =SUM(D15:P15) -> 0
A16: 12 | C16: BBL 5889-9 | Q16: =SUM(D16:P16) -> 0
A17: 13 | C17: BBL 7118-3(K.อดิศักดิ์) | Q17: =SUM(D17:P17) -> 0
A18: 14 | C18: BBL 9250-4(K.อดิศักดิ์&K.ธนู) | Q18: =SUM(D18:P18) -> 0
A19: 15 | C19: CD ส่วนตัว | Q19: =SUM(D19:P19) -> 0
A20: 16 | C20: CEMENT SHOP | Q20: =SUM(D20:P20) -> 0
... A22: 18 | C22: CH-96 | Q22: =SUM(D22:P22) -> 0
A23: 19 | B23: กรรมการ | C23: CH-Exp | Q23: =SUM(D23:P23) -> 0
A24: 20 | C24: CH-Loan | Q24: =SUM(D24:P24) -> 0
A25: 21 | C25: D.N. | Q25: =SUM(D25:P25) -> 0
A26: 22 | C26: DAW YU ส่วนตัว | Q26: =SUM(D26:P26) -> 0
A27: 23 | C27: D-SHOP | Q27: =SUM(D27:P27) -> 0
A28: 24 | C28: EXP C-PAC | Q28: =SUM(D28:P28) -> 0
A29: 25 | C29: Exp KPS | Q29: =SUM(D29:P29) -> 0
A30: 26 | B30: โรงงานมะริด | C30: Exp M-SHOP | Q30: =SUM(D30:P30) -> 0
A31: 27 | C31: Exp MYEIK | Q31: =SUM(D31:P31) -> 0
A32: 28 | C32: Exp RGT | Q32: =SUM(D32:P32) -> 0
A33: 29 | C33: Exp T&Y | Q33: =SUM(D33:P33) -> 0
A34: 30 | C34: Exp RN | Q34: =SUM(D34:P34) -> 0
A35: 31 | C35: Exp VN | Q35: =SUM(D35:P35) -> 0
A36: 32 | C36: EXP VN-14 | Q36: =SUM(D36:P36) -> 0
A37: 33 | C37: Exp แพออ | Q37: =SUM(D37:P37) -> 0
A38: 34 | C38: Fish Market Fee King Star(โกคุ้ยแหง่) | Q38: =SUM(D38:P38) -> 0
A39: 35 | C39: FM | Q39: =SUM(D39:P39) -> 0
A40: 36 | C40: HHT-ICE | Q40: =SUM(D40:P40) -> 0
A41: 37 | C41: HHT IMP-EXP(A- BANK) | Q41: =SUM(D41:P41) -> 0
...

Sheet บัญชีโอน
A1: ลำดับ | B1: ชื่อร้าน | C1: จ่ายให้ | D1: BANK | E1: เลขที่บัญชี | F1: ประเภท | G1: รายละเอียด | H1: LINE
B2: AIA | C2: บจ.เอไอเอ | D2: QR CODE | E2: บจ.เอไอเอ
B3: BBL 1644-3 | C3: นายธนู ทักษิณาวงศ์ | D3: BBL | E3: 527-3-01644-3
B4: BBL 1765-6 | C4: นายอดิศักดิ์ รุจิวิวัฒนกุล | D4: BBL | E4: 527-3-01765-6
B5: BBL 5889-9 | C5: นายธนู ทักษิณาวงศ์ | D5: BBL | E5: 527-0-25889-9
B6: CHO CHO WIN | C6: CHO CHO WIN | D6: Kbank | E6: 085-8-66544-2 | F6: UST | H6: พี่เล็ก
A7: 18 | B7: GHP หนุ่มกระจกอลูมิเนียม | C7: นายยิ่งยศ แก้ววงค์ทอง | D7: BBL | E7: 527-3-01122-0 | F7: ร้านค้า | H7: หนุ่มกระจก
A8: 18 | B8: GHP หนุ่มกระจกอลูมิเนียม | C8: นายยิ่งยศ แก้ววงค์ทอง | D8: Kbank | E8: 032-3-56364-0 | F8: ร้านค้า | H8: หนุ่มกระจก
B9: K.K. Ranong Trading LTD.,PART. | C9: K.K. Ranong Trading LTD.,PART. | D9: Kbank | E9: 232-2-18817-2 | F9: UST | H9: จี้ตะซิน
B10: KS.เทรดดิ้ง | C10: นายเกรียงศักดิ์ แซ่โง้ว | D10: BBL | E10: 128-0-74064-6 | F10: ท่าเรือ | H10: ท่าเรือ
A11: 25 | B11: LYA (พี่เสง) | C11: นายปิยวุฒิ ลิ่มศิลา | D11: TTB | E11: 429-2-25632-0 | F11: ร้านค้า | H11: พี่เสง
B12: MISS GLORIA HUANG | C12: MISS GLORIA HUANG | D12: SCB | E12: 218-2-84081-5 | H12: พี่เล็ก
B13: MISS HSU MYAT HTOO | C13: MISS HSU MYAT HTOO | D13: BAY | E13: 769-1-26336-4
B14: MR. ARKER SOE THEIN | C14: MR. ARKER SOE THEIN | D14: BBL | E14: 037-4-14587-8 | F14: UST | G14: ค่าเทอมลูกชาย | H14: พี่เล็ก
B15: MR. HTAY WIN | C15: MR. HTAY WIN | D15: BBL | E15: 291-0-91259-7 | G15: โรงแรมแกรนด์อันดามัน | H15: โกจุ่ง
B16: MR. KAUNG KYAW MOE | C16: MR. KAUNG KYAW MOE | D16: Kbank | E16: 165-3-16118-9 | F16: ท่าเรือ | H16: ท่าเรือ
B17: MR. KYAW THUYA | C17: MR. KYAW THUYA | D17: BBL | E17: 527-0-24979-9 | F17: GP-ค่าของ | H17: พี่เล็ก
B18: MR. NAING LYNN | C18: MR. NAING LYNN | D18: BBL | E18: 101-9-38598-6 | G18: ค่าปลาฝากขาย | H18: พี่เล็ก
B19: MR. ZAY YAR OO | C19: MR. ZAY YAR OO | D19: Kbank | E19: 106-1-55122-7 | F19: Yส่วนตัว | H19: พี่เล็ก
B20: MR.HEIN THWE ZONE | C20: HEIN THWE ZONE | D20: BBL | E20: 855-0-83084-1 | F20: กลุ่มน้ำมัน | G20: ค่าเจ้าท่าของพม่านำเข้าน้ำมัน | H20: จี้ตะซิน/พี่เล็ก
B21: MR.SOE THEIN | C21: MR.SOE THEIN | D21: BBL | E21: 939-0-28685-5 | F21: UST
B22: MR.SUNTAYA SETAVORAPHAN | C22: MR.SUNTAYA SETAVORAPHAN | D22: BBL | E22: 180-4-97992-8 | F22: ท่าเรือ | H22: ท่าเรือ
B23: MR.THAUNG TUN | C23: MR.THAUNG TUN | D23: Kbank | E23: 140-8-79416-8 | F23: UST
B24: MR.THU KHA AND MRS.AYE AYE MU | C24: MR.THU KHA AND MRS.AYE AYE MU | D24: BBL | E24: 056-0-47678-0 | F24: โกพกส่วนตัว | H24: พี่เล็ก
B25: MR.THUYA AUNG NO SERNAME | C25: MR.THUYA AUNG NO SERNAME | D25: Kbank | E25: 550-2-04642-1 | G25: ค่า% เรืออวนดำ
B26: MR.TIN SOE | C26: MR.TIN SOE | D26: Kbank | E26: 038-3-60121-5 | G26: ค่า Agent ASIAN DAWN CO.,LTD | H26: พี่เล็ก
B27: MR.ZAW MYO TUN | C27: MR.ZAW MYO TUN | D27: BBL | E27: 031-7-11072-4 | F27: KSส่วนตัว | H27: พี่เล็ก
B28: MRS.AYE AYE MU | C28: MRS.AYE AYE MU | D28: BBL | E28: 101-9-36080-7 | F28: SM-ขายปลา | H28: พี่เล็ก
B29: MRS.KHIN HTWE KYI | C29: MRS.KHIN HTWE KYI | D29: BBL | E29: 056-0-47780-4 | F29: โกหัวส่วนตัว | H29: น้าเบิ้ล
B30: MRS.MA AYE NWAY NWAY CHAW | C30: MRS.MA AYE NWAY NWAY CHAW | D30: BBL | E30: 056-0-43520-8 | F30: โกฮุ้ยส่วนตัว | H30: น้าเบิ้ล
B31: MS.MYAT NOE THU | C31: MS.MYAT NOE THU | D31: QR CODE | E31: MS.MYAT NOE THU | F31: Ko Soe Wee/โกซาฮุ่ยส่วนตัว | H31: พี่เล็ก
B32: MS.NAN MI MI KHAING | C32: MS.NAN MI MI KHAING | D32: Kbank | E32: 004-8-95102-3 | F32: ค่าใช้จ่ายเจ้าหน้าที่เฉลี่ย | H32: พี่เล็ก
B33: MS.YIN YIN HTIKE | C33: MS.YIN YIN HTIKE | D33: BBL | E33: 031-7-11073-2 | F33: KSส่วนตัว | H33: จี้ตะซิน
B34: MS.ZIN THU HAN | C34: MS.ZIN THU HAN | D34: P-Pay | E34: 093-XXX-8262 | F34: Exp MYEIK | H34: พี่เล็ก
B35: NT Com | C35: นายนครชัย ทองอนันต์ | D35: QR CODE | E35: นายนครชัย ทองอนันต์ | F35: OFF | G35: อุปกรณ์คอมฯ (ผ่านช่างประพล) | H35: NT Com
A36: 40 | B36: PJ | C36: นายวิโรจน์ จันทปัญญา | D36: Kbank | E36: 016-8-35381-2 | F36: ร้านค้า | H36: PJ - ranong
A37: 49 | B37: PPไฮดรอลิค | C37: นายอัศวกรณ์ มิลินจารุภารัตน์ | D37: Kbank | E37: 098-1-73347-9 | F37: ร้านค้า | H37: ต้อม T.L.ไฮดรอลิค
B38: Pronpimon Oangsuwan | C38: Pronpimon Oangsuwan | D38: Kbank | E38: 138-8-42844-5 | F38: FM | G38: เงินเดือน ELDA | H38: พี่เล็ก
B39: RAM | C39: น.ส.เมธ์วดี รุจิวิวัฒนกุล | D39: KTB | E39: 806-0-43357-1 | F39: โกต้งส่วนตัว | H39: จี้เมธ์
B40: RAM(ตะแกรงไวท์เมช) | C40: น.ส.ธนาภรณ์ รุจิวิวัฒนกุล | D40: TTB | E40: 928-2-03501-4 | F40: โกต้งส่วนตัว | G40: รั้วตะแกรงไวท์เมช | H40: จี้เมธ์
...

Sheet ใบสำคัญจ่าย
H1: RGT | N1: M.Banking
A2: ใบสำคัญจ่าย / PAYMENT VOUCHER
N3: เลขที่ No. | O3: M69-05-003
A4: จ่ายให้ | C4: โกเจี้ยวและครอบครัว | N4: วันที่ Date | O4: =VLOOKUP(O3,'[2]5-69'!$A$3:$J$272,3,0) -> 46143
A5: Paid To
A6: จำนวนเงิน | C6: =+O14 -> 495000 | G6: ธนาคาร | H6: =VLOOKUP(C4,[3]บัญชีโอน!$B$1:$E$700,3,0) -> #N/A | I6: / | J6: =VLOOKUP(C4,[3]บัญชีโอน!$B$2:$E$700,2,0) -> #N/A | M6: / | N6: =VLOOKUP(J6,[3]บัญชีโอน!$C$1:$E$700,3,0) -> #N/A
A7: Amount | G7: Bank
A8: รหัสบัญชี | D8: ชื่อบัญชี | G8: รายการ | O8: จำนวนเงิน(บาท)
A9: A/C No. | D9: A/C | G9: Particulars | O9: Amount
D10: =VLOOKUP(O3,'[2]5-69'!$A$3:$J$272,5,0) -> โกเจี้ยวส่วนตัว | G10: =VLOOKUP(O3,'[2]5-69'!$A$3:$J$272,6,0) -> เงินเดือนโกเจี้ยวและครอบครัว 5.) | O10: =VLOOKUP(O3,'[2]5-69'!$A$3:$J$272,10,0) -> 495000
L14: รวม | O14: =SUM(O10:O13) -> 495000
L15: Total Amount
A16: จำนวนเงินเป็นตัวอักษร | F16: ="("&BAHTTEXT(O14)&")" -> (สี่แสนเก้าหมื่นห้าพันบาทถ้วน)
A17: Amount in words
A18: ผู้อนุมัติ | F18: ผู้จัดทำ | G18: GIFE | J18: ผู้ตรวจสอบ | N18: ผู้รับเงิน
A19: Authorized By | F19: Prepared By | J19: Checked By | N19: Received By
A20: วันที่ | F20: วันที่ | G20: =O4 -> 46143 | J20: วันที่ | N20: วันที่
A21: Date | F21: Date | J21: Date | N21: Date
